<?xml version="1.0" encoding="utf-8"?>


<robot name="humanoid">

<!-- gazebo materials -->

  <material name="black">
    <color rgba="0.0 0.0 0.0 1.0"/>
  </material>
  <material name="blue">
    <color rgba="0.0 0.0 0.8 1.0"/>
  </material>
  <material name="green">
    <color rgba="0.0 0.8 0.0 1.0"/>
  </material>
  <material name="grey">
    <color rgba="0.6 0.6 0.6 1.0"/>
  </material>
  <material name="orange">
    <color rgba="1.0 0.423529411765 0.0392156862745 1.0"/>
  </material>
  <material name="brown">
    <color rgba="0.870588235294 0.811764705882 0.764705882353 1.0"/>
  </material>
  <material name="red">
    <color rgba="0.8 0.0 0.0 1.0"/>
  </material>
  <material name="white">
    <color rgba="1.0 1.0 1.0 1.0"/>
  </material>

<!-- ros_control plugins -->

  <gazebo>
    <plugin name="gazebo_ros_control" filename="libgazebo_ros_control.so">
      <robotNamespace>/humanoid</robotNamespace> 
    </plugin> 
  </gazebo>

  <gazebo>
    <plugin filename="libgazebo_ros_p3d.so" name="ground_truth">
      <frameName>map</frameName>
      <bodyName>base_link</bodyName>
      <topicName>/humanoid/odom</topicName>
      <updateRate>100.0</updateRate>
    </plugin>
  </gazebo>

<!-- IMU -->
  <gazebo reference="IMU_Link">
    <gravity>true</gravity>
    <material>Gazebo/Green</material>
    <sensor name="IMU_Link" type="imu">
      <always_on>true</always_on>
      <update_rate>100</update_rate>
      <visualize>true</visualize>
      <topic>/humanoid/sensor/imu</topic>

      <plugin filename="libgazebo_ros_imu_sensor.so" name="imu_plugin">
        <topicName>humanoid/sensor/imu</topicName>
        <bodyName>IMU_Link</bodyName>
        <updateRateHZ>10.0</updateRateHZ>
        <gaussianNoise>0.0</gaussianNoise>
        <xyzOffset>0 0 0</xyzOffset>
        <rpyOffset>0 0 0</rpyOffset>
        <frameName>IMU_Link</frameName>
      </plugin>
      <pose>0 0 0 0 0 0</pose>
    </sensor>
  </gazebo>

  <!-- World -->
  <gazebo reference="world"/>
  <!-- Map -->
  <gazebo reference="map"/>
  <!-- Base -->
  <gazebo reference="base_link"/>
  <!-- IMU -->
  <gazebo reference="imu_link"/>
  <!-- base -->
  <gazebo reference="base_link">
    <mu1>0.2</mu1>
    <mu2>0.2</mu2>
    <material>Gazebo/Grey</material>
    <selfCollide>false</selfCollide>
  </gazebo>

  <!-- Left Shoulder -->
  <gazebo reference="Left_Upper Shoulder_link">
    <mu1>0.2</mu1>
    <mu2>0.2</mu2>
    <material>Gazebo/Grey</material>
    <selfCollide>false</selfCollide>
  </gazebo>

  <gazebo reference="Left_Mid_Shoulder_Link">
    <mu1>0.2</mu1>
    <mu2>0.2</mu2>
    <material>Gazebo/Grey</material>
    <selfCollide>false</selfCollide>
  </gazebo>

  <gazebo reference="Left_Lower_Shoulder Link">
    <mu1>0.2</mu1>
    <mu2>0.2</mu2>
    <material>Gazebo/Grey</material>
    <selfCollide>false</selfCollide>
  </gazebo>

<!--Right Shoulder -->
  <gazebo reference="Right_Upper_Shoulder_Link">
    <mu1>0.2</mu1>
    <mu2>0.2</mu2>
    <material>Gazebo/Grey</material>
    <selfCollide>false</selfCollide>
  </gazebo>

  <gazebo reference="Right_Mid_Shoulder_link">
    <mu1>0.2</mu1>
    <mu2>0.2</mu2>
    <material>Gazebo/Grey</material>
    <selfCollide>false</selfCollide>
  </gazebo>

  <gazebo reference="Right_Lower_Shoulder_link">
    <mu1>0.2</mu1>
    <mu2>0.2</mu2>
    <material>Gazebo/Grey</material>
    <selfCollide>false</selfCollide>
  </gazebo>

<!--Right Leg -->
  <gazebo reference="Right_Hip_Link">
    <mu1>0.2</mu1>
    <mu2>0.2</mu2>
    <material>Gazebo/Grey</material>
    <selfCollide>false</selfCollide>
  </gazebo>

  <gazebo reference="Right_Thigh_Link">
    <mu1>0.2</mu1>
    <mu2>0.2</mu2>
    <material>Gazebo/Grey</material>
    <selfCollide>false</selfCollide>
  </gazebo>

  <gazebo reference="Right_Calf_Link Link">
    <mu1>0.2</mu1>
    <mu2>0.2</mu2>
    <material>Gazebo/Grey</material>
    <selfCollide>false</selfCollide>
  </gazebo>

  <gazebo reference="Right_Foot_Link">
    <kp>10000.0</kp>
    <kd>100.0</kd>
    <mu1>0.9</mu1>
    <mu2>0.9</mu2>
    <fdir1>1 1 0</fdir1>
    <maxVel>1.0</maxVel>
    <minDepth>0.0001</minDepth>
    <material>Gazebo/Blue</material>
  </gazebo>

<!-- Left Leg -->
  <gazebo reference="Left_Hip_Link">
    <mu1>0.2</mu1>
    <mu2>0.2</mu2>
    <material>Gazebo/Grey</material>
    <selfCollide>false</selfCollide>
  </gazebo>
  <gazebo reference="Left_Thigh_Link">
    <mu1>0.2</mu1>
    <mu2>0.2</mu2>
    <material>Gazebo/Grey</material>
    <selfCollide>false</selfCollide>
  </gazebo>
  <gazebo reference="Left_Calf_Link">
    <mu1>0.2</mu1>
    <mu2>0.2</mu2>
    <material>Gazebo/Grey</material>
    <selfCollide>false</selfCollide>
  </gazebo>
  <gazebo reference="Left_foot_Link">
    <kp>10000.0</kp>
    <kd>100.0</kd>
    <mu1>0.9</mu1>
    <mu2>0.9</mu2>
    <fdir1>1 1 0</fdir1>
    <maxVel>1.0</maxVel>
    <minDepth>0.0001</minDepth>
    <material>Gazebo/Blue</material>
  </gazebo>

<!-- head -->
  <gazebo reference="Head_Horizontal_Link">
    <mu1>0.2</mu1>
    <mu2>0.2</mu2>
    <material>Gazebo/Grey</material>
    <selfCollide>false</selfCollide>
  </gazebo>

  <gazebo reference="Head_Vertical_Link">
    <mu1>0.2</mu1>
    <mu2>0.2</mu2>
    <material>Gazebo/Grey</material>
    <selfCollide>false</selfCollide>
  </gazebo>
<!-- Camera -->
   <gazebo reference="Lens_Link">
    <material>Gazebo/red</material>
    <sensor name="Camera" type="camera">
      <pose> 0 0 0 0 0 0   </pose>
      <visualize>true</visualize>
      <update_rate>100</update_rate>
      <camera>
        <horizontal_fov>1.089</horizontal_fov>
       <image>
          <format>R8G8B8</format>
          <width>640</width>
          <height>480</height>
        </image> 
        <clip>
          <near>0.05</near>
          <far>8.0</far>
        </clip>
      </camera>
      <plugin name="camera_controller" filename="libgazebo_ros_camera.so">
        <frame_name>Lens_Link</frame_name>
	<topicName>humanoid/sensor/camera</topicName>
        <updateRateHZ>10.0</updateRateHZ>
      </plugin>
    </sensor>
  </gazebo>  

<!-- Dummy Link -->
  <link name="dummy">
    </link>

<!-- Dummy Joint -->
  <joint name ="dummy_joint" type="fixed">
	<parent link="dummy" />
	<child link="base_link" />
  </joint>

<!-- Base link -->
  <link
    name="base_link">
    <inertial>
      <origin xyz="0.0430324853400007 -0.000472436994687554 0.418875105300566" rpy="0 0 0" />
      <mass value="1.5156152965091" />
      <inertia
        ixx="0.00479971128253314"
        ixy="-1.53952738629959E-06"
        ixz="-0.000447300525972222"
        iyy="0.0034137294682176"
        iyz="-2.76941918796667E-06"
        izz="0.00294823153121814" />
    </inertial>
    <visual>
      <origin xyz="0 0 0" rpy="0 0 0" />
      <geometry>
        <mesh filename="package://humanoid_descripition/meshes/base_link.STL" />
      </geometry>
      <material name="grey"/>
    </visual>
    <collision>
      <origin
        xyz="0 0 0" rpy="0 0 0" />
      <geometry>
        <mesh filename="package://humanoid_descripition/meshes/base_link.STL" />
      </geometry>
    </collision>
  </link>
<!--Left upper shoulder link -->
  <link
    name="Left_Upper_Shoulder_link">
    <inertial>
      <origin xyz="-3.46944695195361E-18 -0.0155156048759658 -7.21644966006352E-16" rpy="0 0 0" />
      <mass value="0.0623876643494411" />
      <inertia ixx="2.27108792085224E-05" ixy="7.39334846754752E-21" ixz="-3.44731761197701E-21" iyy="3.90809536959519E-05" iyz="-1.53755655815756E-21"  izz="4.97719837636778E-05" />
    </inertial>
    <visual>
      <origin xyz="0 0 0" rpy="0 0 0" />
      <geometry>
        <mesh filename="package://humanoid_descripition/meshes/Left_Upper_Shoulder_link.STL" />
      </geometry>
      <material name="grey"/>
    </visual>
    <collision>
      <origin
        xyz="0 0 0" rpy="0 0 0" />
      <geometry>
        <mesh filename="package://humanoid_descripition/meshes/Left_Upper_Shoulder_link.STL" />
      </geometry>
    </collision>
  </link>

<!-- Left_Upper_Shoulder_Joint -->
  <joint
    name="Left_Upper_Shoulder_Joint" type="revolute">
    <origin xyz="0.045 -0.0862 0.48279"  rpy="0 0 0" />
    <parent link="base_link" />
    <child link="Left_Upper_Shoulder_link" />
    <axis xyz="0 -1 0" />
    <limit lower="-3.14" upper="3.14" effort="8.4" velocity="4.712" />
    <dynamics damping="0.1" friction="0.0"/>
  </joint>

<!-- Left_Upper_Shoulder_Transmission -->
  <transmission name="Left_Upper_Shoulder_transmission">
    <type>transmission_interface/SimpleTransmission</type>
    <joint name="Left_Upper_Shoulder_Joint">
      <hardwareInterface>hardware_interface/EffortJointInterface</hardwareInterface>
    </joint>
    <actuator name="Left_Upper_Shoulder_actuator">
      <hardwareInterface>hardware_interface/EffortJointInterface</hardwareInterface>
      <mechanicalReduction>1</mechanicalReduction>
    </actuator>
  </transmission>

  <link
    name="Left_Mid_Shoulder_Link">
    <inertial>
      <origin xyz="0.0264662969429448 4.09537062595611E-08 -0.0440571522217455" rpy="0 0 0" />
      <mass value="0.154300552543257" />
      <inertia
        ixx="7.07637535997255E-05"
        ixy="-5.19855697944797E-13"
        ixz="-2.88599141150469E-07"
        iyy="9.89041124781951E-05"
        iyz="2.76937890171708E-10"
        izz="6.2961859669379E-05" />
    </inertial>
    <visual>
      <origin xyz="0 0 0" rpy="0 0 0" />
      <geometry>
        <mesh filename="package://humanoid_descripition/meshes/Left_Mid_Shoulder_Link.STL" />
      </geometry>
      <material name="grey"/>
    </visual>
    <collision>
      <origin xyz="0 0 0" rpy="0 0 0" />
      <geometry>
        <mesh filename="package://humanoid_descripition/meshes/Left_Mid_Shoulder_Link.STL" />
      </geometry>
    </collision>
  </link>

<!-- Left_Mid_Shoulder_Joint -->
  <joint name="Left_Mid_Shoulder_Joint" type="revolute">
    <origin xyz="-0.026 -0.0345 0" rpy="0 0 0" />
    <parent link="Left_Upper_Shoulder_link" />
    <child link="Left_Mid_Shoulder_Link" />
    <axis xyz="1 0 0" />
    <limit lower="-3.14" upper="3.14" effort="6" velocity="6.59" />
  </joint>

<!-- Left Mid shoulder transmission -->
  <transmission name="Left_Mid_Shoulder_transmission">
    <type>transmission_interface/SimpleTransmission</type>
    <joint name="Left_Mid_Shoulder_Joint">
      <hardwareInterface>hardware_interface/EffortJointInterface</hardwareInterface>
    </joint>
    <actuator name="Left_Mid_Shoulder_actuator">
      <hardwareInterface>hardware_interface/EffortJointInterface</hardwareInterface>
      <mechanicalReduction>1</mechanicalReduction>
    </actuator>
  </transmission>

<!-- Left Lower Shoulder Link -->
  <link name="Left_Lower_Shoulder_Link">
    <inertial>
      <origin xyz="0.0250664390388209 -0.00638333415263484 -0.0372443138205451" rpy="0 0 0" />
      <mass value="0.116130359952787" />
      <inertia
        ixx="0.000106554804819096"
        ixy="-5.19855704836473E-13"
        ixz="2.8859914115054E-07"
        iyy="0.000115041924032447"
        iyz="5.75846158471286E-06"
        izz="2.6449480887795E-05" />
    </inertial>
    <visual>
      <origin xyz="0 0 0" rpy="0 0 0" />
      <geometry>
        <mesh filename="package://humanoid_descripition/meshes/Left_Lower_Shoulder Link.STL" />
      </geometry>
      <material name="grey"/>
    </visual>
    <collision>
      <origin xyz="0 0 0" rpy="0 0 0" />
      <geometry>
        <mesh filename="package://humanoid_descripition/meshes/Left_Lower_Shoulder Link.STL" />
      </geometry>
    </collision>
  </link>

<!-- Left_Lower_Shoulder_Joint -->
  <joint name="Left_Lower_Shoulder_Joint" type="revolute">
    <origin xyz="0.00230000000000036 0 -0.111599999999999" rpy="0 0 0" />
    <parent link="Left_Mid_Shoulder_Link" />
    <child link="Left_Lower_Shoulder_Link" />
    <axis xyz="1 0 0" />
    <limit lower="-3.14" upper="3.14" effort="6" velocity="6.59" />
  </joint>

<!-- Left_Lower_Shoulder_transmission-->
  <transmission name="Left_Lower_Shoulder_transmission">
    <type>transmission_interface/SimpleTransmission</type>
    <joint name="Left_Lower_Shoulder_Joint">
      <hardwareInterface>hardware_interface/EffortJointInterface</hardwareInterface>
    </joint>
    <actuator name="Left_Lower_Shoulder_actuator">
      <hardwareInterface>hardware_interface/EffortJointInterface</hardwareInterface>
      <mechanicalReduction>1</mechanicalReduction>
    </actuator>
  </transmission>
<!-- Right upper shoulder link -->
  <link name="Right_Upper_Shoulder_Link">
    <inertial>
      <origin xyz="-1.21430643318376E-17 0.015515604875966 -7.49400541621981E-16" rpy="0 0 0" />
      <mass value="0.0623876643494411" />
      <inertia
        ixx="2.27108792085224E-05"
        ixy="-1.28155332543922E-20"
        ixz="-1.24135449919456E-20"
        iyy="3.90809536959519E-05"
        iyz="-1.95476644554543E-22"
        izz="4.97719837636778E-05" />
    </inertial>
    <visual>
      <origin xyz="0 0 0" rpy="0 0 0" />
      <geometry>
        <mesh filename="package://humanoid_descripition/meshes/Right_Upper_Shoulder_Link.STL" />
      </geometry>
      <material name="grey"/>
    </visual>
    <collision>
      <origin xyz="0 0 0" rpy="0 0 0" />
      <geometry>
        <mesh filename="package://humanoid_descripition/meshes/Right_Upper_Shoulder_Link.STL" />
      </geometry>
    </collision>
  </link>

<!-- Right_Upper_Shoulder_Joint -->
  <joint name="Right_Upper_Shoulder_Joint" type="revolute">
    <origin xyz="0.045 0.0862000000000002 0.482793745640598" rpy="0 0 0" />
    <parent link="base_link" />
    <child link="Right_Upper_Shoulder_Link" />
    <axis xyz="0 1 0" />
    <limit lower="-3.14" upper="3.14" effort="8.4" velocity="4.712" />
  </joint>

<!-- Right_Upper_Shoulder_transmission -->
  <transmission name="Right_Upper_Shoulder_transmission">
    <type>transmission_interface/SimpleTransmission</type>
    <joint name="Right_Upper_Shoulder_Joint">
      <hardwareInterface>hardware_interface/EffortJointInterface</hardwareInterface>
    </joint>
    <actuator name="Right_Upper_Shoulder_actuator">
      <hardwareInterface>hardware_interface/EffortJointInterface</hardwareInterface>
      <mechanicalReduction>1</mechanicalReduction>
    </actuator>
  </transmission>
<!-- right mid shoulder link -->
  <link name="Right_Mid_Shoulder_link">
    <inertial>
      <origin xyz="0.0264662969429444 4.09537060375165E-08 -0.044057152221746" rpy="0 0 0" />
      <mass value="0.154300552543257" />
      <inertia
        ixx="7.07637535997256E-05"
        ixy="-5.19855694633109E-13"
        ixz="-2.88599141150464E-07"
        iyy="9.89041124781952E-05"
        iyz="2.76937890187698E-10"
        izz="6.29618596693791E-05" />
    </inertial>
    <visual>
      <origin xyz="0 0 0" rpy="0 0 0" />
      <geometry>
        <mesh filename="package://humanoid_descripition/meshes/Right_Mid_Shoulder_link.STL" />
      </geometry>
      <material
        name="grey"/>
    </visual>
    <collision>
      <origin xyz="0 0 0" rpy="0 0 0" />
      <geometry>
        <mesh filename="package://humanoid_descripition/meshes/Right_Mid_Shoulder_link.STL" />
      </geometry>
    </collision>
  </link>

<!-- Right_Mid_Shoulder_Joint -->
  <joint name="Right_Mid_Shoulder_Joint" type="revolute">
    <origin xyz="-0.026 0.0345 0" rpy="0 0 0" />
    <parent link="Right_Upper_Shoulder_Link" />
    <child link="Right_Mid_Shoulder_link" />
    <axis xyz="1 0 0" />
    <limit lower="-3.14" upper="3.14" effort="6" velocity="6.59" />
  </joint>

<!-- Right_Mid_Shoulder_transmission -->
  <transmission name="Right_Mid_Shoulder_transmission">
    <type>transmission_interface/SimpleTransmission</type>
    <joint name="Right_Mid_Shoulder_Joint">
      <hardwareInterface>hardware_interface/EffortJointInterface</hardwareInterface>
    </joint>
    <actuator name="Right_Mid_Shoulder_actuator">
      <hardwareInterface>hardware_interface/EffortJointInterface</hardwareInterface>
      <mechanicalReduction>1</mechanicalReduction>
    </actuator>
  </transmission>

<!-- Right Lower Shoulder -->
  <link
    name="Right_Lower_Shoulder_link">
    <inertial>
      <origin xyz="0.0250664390388211 0.00638333374995644 -0.0372443138205444" rpy="0 0 0" />
      <mass value="0.116130359952787" />
      <inertia
        ixx="0.000106554804819096"
        ixy="-5.19855699251492E-13"
        ixz="2.88599141150526E-07"
        iyy="0.000115041924032448"
        iyz="-5.75845724996921E-06"
        izz="2.64494808877951E-05" />
    </inertial>
    <visual>
      <origin xyz="0 0 0" rpy="0 0 0" />
      <geometry>
        <mesh filename="package://humanoid_descripition/meshes/Right_Lower_Shoulder_link.STL" />
      </geometry>
      <material name="grey"/>
    </visual>
    <collision>
      <origin xyz="0 0 0" rpy="0 0 0" />
      <geometry>
        <mesh filename="package://humanoid_descripition/meshes/Right_Lower_Shoulder_link.STL" />
      </geometry>
    </collision>
  </link>

<!-- Right_Lower_Shoulder_joint -->
  <joint name="Right_Lower_Shoulder_Joint" type="revolute">
    <origin xyz="0.00230000000000011 0 -0.1116" rpy="0 0 0" />
    <parent link="Right_Mid_Shoulder_link" />
    <child link="Right_Lower_Shoulder_link" />
    <axis xyz="1 0 0" />
    <limit lower="-3.14" upper="3.14" effort="6" velocity="6.59" />
  </joint>

<!-- Right_Lower_Shoulder_transmission -->
  <transmission name="Right_Lower_Shoulder_transmission">
    <type>transmission_interface/SimpleTransmission</type>
    <joint name="Right_Lower_Shoulder_Joint">
      <hardwareInterface>hardware_interface/EffortJointInterface</hardwareInterface>
    </joint>
    <actuator name="Right_Lower_Shoulder_actuator">
      <hardwareInterface>hardware_interface/EffortJointInterface</hardwareInterface>
      <mechanicalReduction>1</mechanicalReduction>
    </actuator>
  </transmission>

<!--Right Hip Link -->

  <link name="Right_Hip_Link">
    <inertial>
      <origin xyz="-1.90819582357449E-17 8.5868812060852E-17 -0.0108026519831324" rpy="0 0 0" />
      <mass value="0.0642422648022387" />
      <inertia
        ixx="4.229626009049E-05"
        ixy="-2.85610366578733E-21"
        ixz="-1.1809768368682E-20"
        iyy="1.91108022562779E-05"
        iyz="-6.6452799051975E-21"
        izz="4.09654383516233E-05" />
    </inertial>
    <visual>
      <origin xyz="0 0 0" rpy="0 0 0" />
      <geometry>
        <mesh filename="package://humanoid_descripition/meshes/Right_Hip_Link.STL" />
      </geometry>
      <material name="grey" />
    </visual>
    <collision>
      <origin xyz="0 0 0" rpy="0 0 0" />
      <geometry>
        <mesh filename="package://humanoid_descripition/meshes/Right_Hip_Link.STL" />
      </geometry>
    </collision>
  </link>

<!-- Right_Hip_Joint -->
  <joint name="Right_Hip_Joint" type="revolute">
    <origin xyz="0.045 0.0576361191366068 0.323180000000002" rpy="0 0 0" />
    <parent link="base_link" />
    <child link="Right_Hip_Link" />
    <axis xyz="0 0 1" />
    <limit lower="-3.14" upper="3.14" effort="8.4" velocity="4.712" />
  </joint>

<!-- Right_Hip_Joint_transmission -->
  <transmission name="Right_Hip_Joint_transmission">
    <type>transmission_interface/SimpleTransmission</type>
    <joint name="Right_Hip_Joint">
      <hardwareInterface>hardware_interface/EffortJointInterface</hardwareInterface>
    </joint>
    <actuator name="Right_Hip_Joint_motor">
      <hardwareInterface>hardware_interface/EffortJointInterface</hardwareInterface>
      <mechanicalReduction>1</mechanicalReduction>
    </actuator>
  </transmission>
<!-- Right Thigh Link -->
  <link name="Right_Thigh_Link">
    <inertial>
      <origin xyz="0.000423342095901284 -0.026447064925249 -0.0636339184538543" rpy="0 0 0" />
      <mass value="0.329164377734902" />
      <inertia
        ixx="0.000243462631907648"
        ixy="2.02833424750188E-07"
        ixz="4.17202887012631E-06"
        iyy="0.000198542286401605"
        iyz="-4.45660040213608E-06"
        izz="0.000113461408846216" />
    </inertial>
    <visual>
      <origin xyz="0 0 0" rpy="0 0 0" />
      <geometry>
        <mesh filename="package://humanoid_descripition/meshes/Right_Thigh_Link.STL" />
      </geometry>
      <material name="grey"/>
    </visual>
    <collision>
      <origin xyz="0 0 0" rpy="0 0 0" />
      <geometry>
        <mesh filename="package://humanoid_descripition/meshes/Right_Thigh_Link.STL" />
      </geometry>
    </collision>
  </link>

<!-- Right_Thigh_Joint -->
  <joint name="Right_Thigh_Joint" type="revolute">
    <origin xyz="0 0.026 -0.025" rpy="0 0 0" />
    <parent link="Right_Hip_Link" />
    <child link="Right_Thigh_Link" />
    <axis xyz="0 1 0" />
    <limit lower="-3.14" upper="3.14" effort="6" velocity="6.59" />
  </joint>

<!-- Right_Thigh_Joint_transmission -->
  <transmission name="Right_Thigh_Joint_transmission">
    <type>transmission_interface/SimpleTransmission</type>
    <joint name="Right_Thigh_Joint">
      <hardwareInterface>hardware_interface/EffortJointInterface</hardwareInterface>
    </joint>
    <actuator name="Right_Thigh_Joint_motor">
      <hardwareInterface>hardware_interface/EffortJointInterface</hardwareInterface>
      <mechanicalReduction>1</mechanicalReduction>
    </actuator>
  </transmission>

<!-- Right Calf Link -->

  <link name="Right_Calf_Link">
    <inertial>
      <origin xyz="-3.34420367410423E-07 -0.026027708615202 -0.0719996537867291" rpy="0 0 0" />
      <mass value="0.278454532534902" />
      <inertia
        ixx="0.000388064654467613"
        ixy="5.19855683036761E-13"
        ixz="5.41021302044064E-09"
        iyy="0.00033610996778635"
        iyz="-2.88599141150599E-07"
        izz="0.00014525331851066" />
    </inertial>
    <visual>
      <origin xyz="0 0 0" rpy="0 0 0" />
      <geometry>
        <mesh filename="package://humanoid_descripition/meshes/Right_Calf_Link.STL" />
      </geometry>
      <material name="grey"/>
    </visual>
    <collision>
      <origin xyz="0 0 0" rpy="0 0 0" />
      <geometry>
        <mesh filename="package://humanoid_descripition/meshes/Right_Calf_Link.STL" />
      </geometry>
    </collision>
  </link>

<!-- Right_Calf_Joint -->
  <joint name="Right_Calf_Joint" type="revolute">
    <origin xyz="0.002 -0.002 -0.12045" rpy="0 0 0" />
    <parent link="Right_Thigh_Link" />
    <child link="Right_Calf_Link" />
    <axis xyz="0 -1 0" />
    <limit lower="-3.14" upper="3.14" effort="6" velocity="6.59" />
  </joint>

<!-- Right_Calf_Joint_transmission -->
  <transmission name="Right_Calf_Joint_transmission">
    <type>transmission_interface/SimpleTransmission</type>
    <joint name="Right_Calf_Joint">
      <hardwareInterface>hardware_interface/EffortJointInterface</hardwareInterface>
    </joint>
    <actuator name="Right_Calf_Joint_motor">
      <hardwareInterface>hardware_interface/EffortJointInterface</hardwareInterface>
      <mechanicalReduction>1</mechanicalReduction>
    </actuator>
  </transmission>
<!-- Right Foot Link -->

  <link name="Right_Foot_Link">
    <inertial>
      <origin xyz="-0.0228837014877897 -0.026033712987681 -0.0155273675416017" rpy="0 0 0" />
      <mass value="0.228265252831077" />
      <inertia
        ixx="6.37874197438039E-05"
        ixy="-2.88491769040962E-07"
        ixz="7.76246022841811E-06"
        iyy="0.000236185068163753"
        iyz="-2.63248093227894E-09"
        izz="0.000274017281441223" />
    </inertial>
    <visual>
      <origin xyz="0 0 0"  rpy="0 0 0" />
      <geometry>
        <mesh filename="package://humanoid_descripition/meshes/Right_Foot_Link.STL" />
      </geometry>
      <material name="grey"/>
    </visual>
    <collision>
      <origin xyz="0 0 0" rpy="0 0 0" />
      <geometry>
        <mesh filename="package://humanoid_descripition/meshes/Right_Foot_Link.STL" />
      </geometry>
    </collision>
  </link>

<!-- Right_Foot_Joint -->
  <joint name="Right_Foot_Joint" type="fixed">
    <origin xyz="0 0 -0.14763" rpy="0 0 0" />
    <parent link="Right_Calf_Link" />
    <child link="Right_Foot_Link" />
    <axis xyz="0 1 0" />
    <limit lower="-3.14" upper="3.14" effort="6" velocity="6.59" />
  </joint>

<!-- Right_Foot_Joint_transmission -->
 <!-- <transmission name="Right_Foot_Joint_transmission">
    <type>transmission_interface/SimpleTransmission</type>
    <joint name="Right_Foot_Joint">
      <hardwareInterface>hardware_interface/EffortJointInterface</hardwareInterface>
    </joint>
    <actuator name="Right_Foot_Joint_motor">
      <hardwareInterface>hardware_interface/EffortJointInterface</hardwareInterface>
      <mechanicalReduction>1</mechanicalReduction>
    </actuator>
  </transmission> --> 

<!-- Left Hip Link -->
  <link name="Left_Hip_Link">
    <inertial>
      <origin xyz="-1.21430643318376E-17 1.38777878078145E-17 -0.0108026519831324" rpy="0 0 0" />
      <mass value="0.0642422648022388" />
      <inertia
        ixx="4.22962600904901E-05"
        ixy="-2.93588493303712E-21"
        ixz="-1.50763911535534E-20"
        iyy="1.9110802256278E-05"
        iyz="-3.29932625471404E-20"
        izz="4.09654383516233E-05" />
    </inertial>
    <visual>
      <origin xyz="0 0 0" rpy="0 0 0" />
      <geometry>
        <mesh filename="package://humanoid_descripition/meshes/Left_Hip_Link.STL" />
      </geometry>
      <material name="grey"/>
    </visual>
    <collision>
      <origin xyz="0 0 0" rpy="0 0 0" />
      <geometry>
        <mesh filename="package://humanoid_descripition/meshes/Left_Hip_Link.STL" />
      </geometry>
    </collision>
  </link>

<!-- Left_Hip_Joint -->
  <joint name="Left_Hip_Joint" type="revolute">
    <origin xyz="0.045 -0.0576361191366066 0.323180000000002" rpy="0 0 0" />
    <parent link="base_link" />
    <child link="Left_Hip_Link" />
    <axis xyz="0 0 1" />
    <limit lower="-3.14" upper="3.14" effort="8.4" velocity="4.712" />
  </joint>

<!-- Left_Hip_Joint_transmission -->
  <transmission name="Left_Hip_Joint_transmission">
    <type>transmission_interface/SimpleTransmission</type>
    <joint name="Left_Hip_Joint">
      <hardwareInterface>hardware_interface/EffortJointInterface</hardwareInterface>
    </joint>
    <actuator name="Left_Hip_Joint_motor">
      <hardwareInterface>hardware_interface/EffortJointInterface</hardwareInterface>
      <mechanicalReduction>1</mechanicalReduction>
    </actuator>
  </transmission>

<!-- Left Thigh Link -->
  <link name="Left_Thigh_Link">
    <inertial>
      <origin xyz="0.000345721545497979 0.0255998149318385 -0.0636339184538543" rpy="0 0 0" />
      <mass value="0.329164377734902" />
      <inertia
        ixx="0.000243462631907648"
        ixy="2.02833424750158E-07"
        ixz="4.17202453538254E-06"
        iyy="0.000198542286401605"
        iyz="-3.87940211983504E-06"
        izz="0.000113461408846216" />
    </inertial>
    <visual>
      <origin xyz="0 0 0" rpy="0 0 0" />
      <geometry>
        <mesh filename="package://humanoid_descripition/meshes/Left_Thigh_Link.STL" />
      </geometry>
      <material name="grey"/>
    </visual>
    <collision>
      <origin xyz="0 0 0" rpy="0 0 0" />
      <geometry>
        <mesh filename="package://humanoid_descripition/meshes/Left_Thigh_Link.STL" />
      </geometry>
    </collision>
  </link>

<!-- Left_Thigh_joint -->
  <joint name="Left_Thigh_joint" type="revolute">
    <origin xyz="0 -0.026 -0.025" rpy="0 0 0" />
    <parent link="Left_Hip_Link" />
    <child link="Left_Thigh_Link" />
    <axis xyz="0 1 0" />
    <limit lower="-3.14" upper="3.14" effort="6" velocity="6.59" />
  </joint>

<!-- Left_Thigh_joint_transmission -->
  <transmission name="Left_Thigh_joint_transmission">
    <type>transmission_interface/SimpleTransmission</type>
    <joint name="Left_Thigh_joint">
      <hardwareInterface>hardware_interface/EffortJointInterface</hardwareInterface>
    </joint>
    <actuator name="Left_Thigh_joint_motor">
      <hardwareInterface>hardware_interface/EffortJointInterface</hardwareInterface>
      <mechanicalReduction>1</mechanicalReduction>
    </actuator>
  </transmission>

  <link name="Left_Calf_Link">
    <inertial>
      <origin xyz="-3.34420367405219E-07 0.0259722913847975 -0.0719996537867291" rpy="0 0 0" />
      <mass value="0.278454532534902" />
      <inertia
        ixx="0.000388064654467613"
        ixy="5.19855688294565E-13"
        ixz="5.41021302046885E-09"
        iyy="0.00033610996778635"
        iyz="-2.88599141150536E-07"
        izz="0.00014525331851066" />
    </inertial>
    <visual>
      <origin xyz="0 0 0" rpy="0 0 0" />
      <geometry>
        <mesh filename="package://humanoid_descripition/meshes/Left_Calf_Link.STL" />
      </geometry>
      <material name="grey"/>
    </visual>
    <collision>
      <origin xyz="0 0 0" rpy="0 0 0" />
      <geometry>
        <mesh filename="package://humanoid_descripition/meshes/Left_Calf_Link.STL" />
      </geometry>
    </collision>
  </link>

<!-- Left_Calf_Joint -->
  <joint name="Left_Calf_Joint" type="revolute">
    <origin xyz="0.00190000000000006 -0.00199999999999997 -0.12045" rpy="0 0 0" />
    <parent link="Left_Thigh_Link" />
    <child link="Left_Calf_Link" />
    <axis xyz="0 1 0" />
    <limit lower="-3.14" upper="3.14" effort="6" velocity="6.59" />
  </joint>

<!-- Left_Calf_Joint_transmission -->
  <transmission name="Left_Calf_Joint_transmission">
    <type>transmission_interface/SimpleTransmission</type>
    <joint name="Left_Calf_Joint">
      <hardwareInterface>hardware_interface/EffortJointInterface</hardwareInterface>
    </joint>
    <actuator name="Left_Calf_Joint_motor">
      <hardwareInterface>hardware_interface/EffortJointInterface</hardwareInterface>
      <mechanicalReduction>1</mechanicalReduction>
    </actuator>
  </transmission>

<!-- left foot link -->
  <link name="Left_foot_Link">
    <inertial>
      <origin xyz="-0.0262701178208457 0.0259662870152242 -0.0155273676418208" rpy="0 0 0" />
      <mass value="0.22826527251043" />
      <inertia
        ixx="6.37874230678566E-05"
        ixy="-2.88491768747918E-07"
        ixz="7.76245967268685E-06"
        iyy="0.000236185196776109"
        iyz="-2.6324809009678E-09"
        izz="0.000274017413123349" />
    </inertial>
    <visual>
      <origin xyz="0 0 0" rpy="0 0 0" />
      <geometry>
        <mesh filename="package://humanoid_descripition/meshes/Left_foot_Link.STL" />
      </geometry>
      <material name="grey"/>
    </visual>
    <collision>
      <origin xyz="0 0 0" rpy="0 0 0" />
      <geometry>
        <mesh filename="package://humanoid_descripition/meshes/Left_foot_Link.STL" />
      </geometry>
    </collision>
  </link>

<!-- Left_foot_Joint -->
  <joint name="Left_foot_Joint" type="fixed">
    <origin xyz="0 0 -0.14763" rpy="0 0 0" />
    <parent link="Left_Calf_Link" />
    <child link="Left_foot_Link" />
    <axis xyz="0 1 0" />
    <limit lower="-3.14" upper="3.14" effort="6" velocity="6.59" />
  </joint>

<!-- Left_foot_Joint_transmission -->
 <!-- <transmission name="Left_foot_Joint_transmission">
    <type>transmission_interface/SimpleTransmission</type>
    <joint name="Left_foot_Joint">
      <hardwareInterface>hardware_interface/EffortJointInterface</hardwareInterface>
    </joint>
    <actuator name="Left_foot_Joint_motor">
      <hardwareInterface>hardware_interface/EffortJointInterface</hardwareInterface>
      <mechanicalReduction>1</mechanicalReduction>
    </actuator>
  </transmission> -->

<!-- Head Horizontal -->
  <link name="Head_Horizontal_Link">
    <inertial>
      <origin xyz="-7.84676299232095E-06 0.00200378386470303 0.0485306889790276" rpy="0 0 0" />
      <mass value="0.304581604639682" />
      <inertia
        ixx="0.000344223992822679"
        ixy="3.23416736024759E-08"
        ixz="2.14300139927456E-08"
        iyy="0.00025250434561587"
        iyz="1.03645901492193E-05"
        izz="0.000226309827320736" />
    </inertial>
    <visual>
      <origin xyz="0 0 0" rpy="0 0 0" />
      <geometry>
        <mesh filename="package://humanoid_descripition/meshes/Head_Horizontal_Link.STL" />
      </geometry>
      <material name="grey"/>
    </visual>
    <collision>
      <origin xyz="0 0 0" rpy="0 0 0" />
      <geometry>
        <mesh filename="package://humanoid_descripition/meshes/Head_Horizontal_Link.STL" />
      </geometry>
    </collision>
  </link>

<!-- Head_Horizontal_Joint -->
  <joint name="Head_Horizontal_Joint" type="revolute">
    <origin xyz="0.0299 0 0.524230000000002" rpy="0 0 0" />
    <parent link="base_link" />
    <child link="Head_Horizontal_Link" />
    <axis xyz="0 0 1" />
    <limit lower="-3.14" upper="3.14" effort="1.078" velocity="6.159" />
  </joint>

<!-- Head_Horizontal_transmission -->
  <transmission name="Head_Horizontal_transmission">
    <type>transmission_interface/SimpleTransmission</type>
    <joint name="Head_Horizontal_Joint">
      <hardwareInterface>hardware_interface/EffortJointInterface</hardwareInterface>
    </joint>
    <actuator name="Head_Horizontal_actuator">
      <hardwareInterface>hardware_interface/EffortJointInterface</hardwareInterface>
      <mechanicalReduction>1</mechanicalReduction>
    </actuator>
  </transmission>

<!-- Head Vertical Link -->
  <link name="Head_Vertical_Link">
    <inertial>
      <origin xyz="-0.00797403135381314 0.0257820432407305 -0.00633555775851055" rpy="0 0 0" />
      <mass value="0.0336929106124403" />
      <inertia
        ixx="1.23288476738391E-05"
        ixy="1.61107638845834E-07"
        ixz="7.16221856208835E-07"
        iyy="1.33519522742047E-05"
        iyz="-1.33901765257804E-07"
        izz="3.28226792350189E-06" />
    </inertial>
    <visual>
      <origin xyz="0 0 0" rpy="0 0 0" />
      <geometry>
        <mesh filename="package://humanoid_descripition/meshes/Head_Vertical_Link.STL" />
      </geometry>
      <material name="grey"/>
    </visual>
    <collision>
      <origin xyz="0 0 0" rpy="0 0 0" />
      <geometry>
        <mesh filename="package://humanoid_descripition/meshes/Head_Vertical_Link.STL" />
      </geometry>
    </collision>
  </link>

<!-- Head_Vertical_Joint -->
  <joint name="Head_Vertical_Joint" type="revolute">
    <origin xyz="4.2275E-05 -0.0285 0.0515" rpy="0 0 0" />
    <parent link="Head_Horizontal_Link" />
    <child link="Head_Vertical_Link" />
    <axis xyz="0 0 1" />
    <limit lower="-3.14" upper="3.14" effort="1.078" velocity="6.159" />
  </joint>

<!-- Head_Vertical_transmission -->
  <transmission name="Head_Vertical_transmission">
    <type>transmission_interface/SimpleTransmission</type>
    <joint name="Head_Vertical_Joint">
      <hardwareInterface>hardware_interface/EffortJointInterface</hardwareInterface>
    </joint>
    <actuator name="Head_Vertical_actuator">
      <hardwareInterface>hardware_interface/EffortJointInterface</hardwareInterface>
      <mechanicalReduction>1</mechanicalReduction>
    </actuator>
  </transmission>
<!-- Camera joint -->
    <joint name="Camera_Joint" type="fixed">
      <parent link="Head_Vertical_Link"/>
      <child link="Camera_Link"/>
      <origin xyz="0 0 0" rpy="0 0 0"/>
    </joint> 
<!-- Camera link -->

  <link name="Camera_Link">
    <inertial>
      <origin
        xyz="-0.02964 0.054262 0.14599"
        rpy="0 0 0" />
      <axis
        xyz="0 0 0" />
      <mass value="0" />
      <inertia
        ixx="1.23288476738391E-05"
        ixy="1.61107638845834E-07"
        ixz="7.16221856208835E-07"
        iyy="1.33519522742047E-05"
        iyz="-1.33901765257804E-07"
        izz="3.28226792350189E-06" />
    </inertial>
    <visual>
      <origin xyz="0 0 0" rpy="0 0 0" />
      <geometry>
      <mesh filename="package://humanoid_descripition/meshes/Camera.STL" />
     </geometry>
     <material name="blue"/>
    </visual>
  </link> 
  <!--Lens_Link-->
  <link
    name="Lens_Link">
    <inertial>
      <origin
        xyz="0.0296402873307111 0.0542620041023058 -0.145993241395755"
        rpy="0 0 0" />
      <mass
        value="0" />
     <inertia
        ixx="1.23288476738391E-05"
        ixy="1.61107638845834E-07"
        ixz="7.16221856208835E-07"
        iyy="1.33519522742047E-05"
        iyz="-1.33901765257804E-07"
        izz="3.28226792350189E-06" />
    </inertial>
   
  </link>
   <!--Lens_Joint--> 
  <joint
    name="Lens_joint"
    type="fixed">
    <origin
      xyz="-0.0249627342624163 0.0274630025807885 0.000388603128653991"
      rpy="-3.14159265358979 -0.0155915295359344 -3.14010933670462" />
    <parent
      link="Head_Vertical_Link" />
    <child
      link="Lens_Link" />
    <axis
      xyz="0 0 0" />
  </joint> 
<link
    name="IMU_Link">
    <inertial>
      <origin
        xyz="0.010731 -0.00061872 -0.27685"
        rpy="0 0 0" />
      <mass
        value="0.000704900526624758" />
      <inertia
        ixx="3.83469081842287E-08"
        ixy="-1.03709665858922E-09"
        ixz="-2.11183830250688E-10"
        iyy="1.37853263734955E-08"
        iyz="-1.61145026935895E-11"
        izz="5.18252315581656E-08" />
    </inertial>
    <visual>
      <origin
        xyz="0 0 0"
        rpy="0 0 0" />
      <geometry>
        <mesh
          filename="package://humanoid_descripition/meshes/IMU.STL" />
      </geometry>
      <material
        name="blue">
        <color
          rgba="0.666666666666667 0.698039215686274 0.768627450980392 1" />
      </material>
    </visual>
    <collision>
      <origin
        xyz="0 0 0"
        rpy="0 0 0" />
      <geometry>
        <mesh
          filename="package://humanoid_descripition/meshes/IMU.STL" />
      </geometry>
    </collision>
  </link>
  <joint
    name="IMU_Joint"
    type="fixed">
    <origin
      xyz="0.00022338 0.00015602 0.0"
      rpy="0 0 0" />
    <parent
      link="Head_Horizontal_Link" />
    <child
      link="IMU_Link" />
    <axis
      xyz="0 0 0" />
  </joint>
</robot> 
